<?xml version="1.0" ?>
<!-- =================================================================================== -->
<!-- |    This document was autogenerated by xacro from mtm_right.urdf.xacro           | -->
<!-- |    EDITING THIS FILE BY HAND IS NOT RECOMMENDED                                 | -->
<!-- =================================================================================== -->
<robot name="master" xmlns:xacro="http://ros.org/wiki/xacro">
  <!-- Macros -->
  <!-- Colors -->
  <!-- Mathematical Constants -->
  <!-- Colors -->
  <material name="DaVinciWhite">
    <color rgba="1.0 1.0 1.0 1"/>
  </material>
  <material name="DaVinciLightGray">
    <color rgba="0.8 0.8 0.8 1"/>
  </material>
  <material name="DaVinciMedGray">
    <color rgba="0.6 0.6 0.6 1"/>
  </material>
  <material name="DaVinciDarkGray">
    <color rgba="0.4 0.4 0.4 1"/>
  </material>
  <material name="DaVinciRed">
    <color rgba="0.5 0.4 0.4 1"/>
  </material>
  <material name="DaVinciGreen">
    <color rgba="0.4 0.5 0.4 1"/>
  </material>
  <material name="DaVinciBlue">
    <color rgba="0.4 0.4 0.5 1"/>
  </material>
  <!-- Macro for the da Vinci Master Console -->
  <!-- Macros for left and right MTMs -->
  <!-- Macro for da Vinci Master Tool Manipulator (MTM) -->
  <link name="world"/>
  <joint name="right_fixed_joint" type="fixed">
    <parent link="world"/>
    <child link="right_top_panel"/>
    <origin rpy="0.0 0.0 0.0" xyz="1.0 0.0 1.0"/>
  </joint>
  <link name="right_top_panel">
    <visual>
      <geometry>
        <mesh filename="package://dvrk_model/meshes/mtm/Top Panel.dae"/>
      </geometry>
    </visual>
    <collision>
      <geometry>
        <mesh filename="package://dvrk_model/meshes/mtm/Top Panel.STL"/>
      </geometry>
    </collision>
    <inertial>
      <origin rpy="0 0 0" xyz="0 0 0"/>
      <mass value=".9"/>
      <inertia ixx="9.0" ixy="0.0" ixz="0.0" iyy="9.0" iyz="0.0" izz="9.0"/>
    </inertial>
  </link>
  <joint name="right_outer_yaw_joint" type="revolute">
    <parent link="right_top_panel"/>
    <child link="right_outer_yaw_link"/>
    <origin rpy="0 0 1.57079632679" xyz="0 0 0"/>
    <axis xyz="0 0 1"/>
    <!--rotates about z axis-->
    <!--limit effort and velocity picked arbitrarily check-->
    <limit effort="50.0" lower="-1.308996939" upper="0.785398163397" velocity="2"/>
    <joint_properties damping="1.0" friction="0.0"/>
  </joint>
  <link name="right_outer_yaw_link">
    <visual>
      <geometry>
        <mesh filename="package://dvrk_model/meshes/mtm/OutPitch_Shoulder.dae"/>
      </geometry>
    </visual>
    <collision>
      <geometry>
        <mesh filename="package://dvrk_model/meshes/mtm/OutPitch_Shoulder.STL"/>
      </geometry>
    </collision>
    <inertial>
      <mass value="1"/>
      <inertia ixx="10.0" ixy="0.0" ixz="0.0" iyy="10.0" iyz="0.0" izz="10.0"/>
    </inertial>
  </link>
  <link name="right_back_parallel_link">
    <visual>
      <geometry>
        <mesh filename="package://dvrk_model/meshes/mtm/ArmParallel.dae"/>
      </geometry>
    </visual>
    <collision>
      <geometry>
        <mesh filename="package://dvrk_model/meshes/mtm/ArmParallel.STL"/>
      </geometry>
    </collision>
    <inertial>
      <mass value=".9"/>
      <inertia ixx="9.0" ixy="0.0" ixz="0.0" iyy="9.0" iyz="0.0" izz="9.0"/>
    </inertial>
  </link>
  <link name="right_top_parallel_link">
    <visual>
      <geometry>
        <mesh filename="package://dvrk_model/meshes/mtm/ArmParallel1.dae"/>
      </geometry>
    </visual>
    <collision>
      <geometry>
        <mesh filename="package://dvrk_model/meshes/mtm/ArmParallel1.STL"/>
      </geometry>
    </collision>
    <inertial>
      <mass value=".5"/>
      <inertia ixx="5.0" ixy="0.0" ixz="0.0" iyy="5.0" iyz="0.0" izz="5.0"/>
    </inertial>
  </link>
  <!--link name="${prefix}front_parallel_link"> 
       <visual> 
         <geometry> 
           <mesh filename="package://dvrk_model/meshes/mtm/Link.dae"/> 
         </geometry> 
       </visual> 
       <collision> 
         <geometry> 
           <mesh filename="package://dvrk_model/meshes/mtm/Link.STL"/> 
         </geometry> 
       </collision> 
       <inertial> 
         <mass value="0.8"/> 
         <inertia ixx="8.0" ixy="0.0" ixz="0.0" iyy="8.0" iyz="0.0" izz="8.0"/>
       </inertial>  
     </link-->
  <joint name="right_shoulder_pitch_joint" type="revolute">
    <parent link="right_outer_yaw_link"/>
    <child link="right_back_parallel_link"/>
    <!-- xyz= 0 0 -.19037-->
    <origin rpy="-1.57079632679 -1.57079632679 0" xyz="0 0 -0.19037"/>
    <axis xyz="0 0 1"/>
    <!--rotates about  x axis-->
    <!--limit effort and velocity picked arbitrarily check-->
    <limit effort="100.0" lower="-0.785398163397" upper="0.785398163397" velocity="10"/>
    <joint_properties damping="1.0" friction="0.0"/>
  </joint>
  <joint name="right_shoulder_pitch_parallel_joint" type="revolute">
    <parent link="right_back_parallel_link"/>
    <child link="right_top_parallel_link"/>
    <origin rpy="0 0 -1.57079632679" xyz="0 0 0.065"/>
    <axis xyz="0 0 1"/>
    <!--rotates about  x axis-->
    <!--limit effort and velocity picked arbitrarily check-->
    <limit effort="100.0" lower="-1.57079632679" upper="1.57079632679" velocity="10"/>
    <joint_properties damping="1.0" friction="0.0"/>
    <mimic joint="right_elbow_pitch_joint" multiplier="1"/>
  </joint>
  <!--joint name="${prefix}elbow_pitch_parallel_joint" type="revolute"> 
       <parent link="${prefix}top_parallel_link"/> 
       <child link="${prefix}front_parallel_link"/> 
       <origin rpy="0 0 0" xyz=".1011 0 -0.03"/> 
       <axis xyz="0 0 1"/> 
       <limit effort="100.0" lower="${-PI/4}" upper="${PI/4}" velocity="10"/> 
       <joint_properties damping="1.0" friction="0.0"/> 
       <mimic joint="${prefix}elbow_pitch_joint" multiplier="-1"/>
     </joint-->
  <joint name="right_elbow_pitch_joint" type="revolute">
    <parent link="right_back_parallel_link"/>
    <child link="right_bottom_parallel_link"/>
    <!-- xyz= -->
    <origin rpy="0 0 1.57079632679" xyz="-.2794 0 0"/>
    <axis xyz="0 0 1"/>
    <!--rotates about x axis-->
    <!--limit effort and velocity picked arbitrarily check-->
    <limit effort="100.0" lower="-0.785398163397" upper="0.785398163397" velocity="10"/>
    <joint_properties damping="1.0" friction="0.0"/>
  </joint>
  <joint name="right_wrist_platform_joint" type="revolute">
    <parent link="right_bottom_parallel_link"/>
    <child link="right_wrist_platform_link"/>
    <!-- -.348 & -.02746 defined from MTMDaVinci paper and  added -.01 from original to align, -0.02746 defined from CAD file-->
    <origin rpy="1.57079632679 0 0" xyz="-0.3645 -0.156 0.0"/>
    <axis xyz="0 0 1"/>
    <!--rotates about z axis-->
    <!--limit effort and velocity picked arbitrarily check-->
    <limit effort="100.0" lower="-1.0471975512" upper="4.27605666739" velocity="10"/>
    <joint_properties damping="1.0" friction="0.0"/>
  </joint>
  <link name="right_wrist_platform_link">
    <visual>
      <geometry>
        <mesh filename="package://dvrk_model/meshes/mtm/WristPlatform.dae"/>
      </geometry>
    </visual>
    <collision>
      <geometry>
        <mesh filename="package://dvrk_model/meshes/mtm/WristPlatform.STL"/>
      </geometry>
    </collision>
    <inertial>
      <mass value="0.4"/>
      <inertia ixx="0.1" ixy="0.0" ixz="0.0" iyy="0.1" iyz="0.0" izz="0.1"/>
    </inertial>
  </link>
  <link name="right_bottom_parallel_link">
    <visual>
      <geometry>
        <mesh filename="package://dvrk_model/meshes/mtm/BottomArm.dae"/>
      </geometry>
    </visual>
    <collision>
      <geometry>
        <mesh filename="package://dvrk_model/meshes/mtm/BottomArm.STL"/>
      </geometry>
    </collision>
    <inertial>
      <mass value="0.8"/>
      <inertia ixx="0.1" ixy="0.0" ixz="0.0" iyy="0.1" iyz="0.0" izz="0.1"/>
    </inertial>
  </link>
  <joint name="right_wrist_pitch_joint" type="revolute">
    <parent link="right_wrist_platform_link"/>
    <child link="right_wrist_pitch_link"/>
    <!--rpy="1.57 0 3.14159 " the num .072 & .123 are defined from CAD file -->
    <origin rpy="-1.57079632679 0 0" xyz="0 0 0"/>
    <axis xyz="0 0 1"/>
    <!--rotates about x axis-->
    <!--limit effort and velocity picked arbitrarily check-->
    <limit effort="100.0" lower="-1.57079632679" upper="3.14159265359" velocity="10"/>
    <joint_properties damping="1.0" friction="0.0"/>
  </joint>
  <link name="right_wrist_pitch_link">
    <visual>
      <!-- defined from CAD file (increased in the y dir by .005-->
      <geometry>
        <mesh filename="package://dvrk_model/meshes/mtm/WristPitch.dae"/>
      </geometry>
    </visual>
    <collision>
      <!-- defined from CAD file (increased in the y dir by .005-->
      <geometry>
        <mesh filename="package://dvrk_model/meshes/mtm/WristPitch.STL"/>
      </geometry>
    </collision>
    <inertial>
      <mass value="0.2"/>
      <inertia ixx="0.1" ixy="0.0" ixz="0.0" iyy="0.1" iyz="0.0" izz="0.1"/>
    </inertial>
  </link>
  <joint name="right_wrist_yaw_joint" type="revolute">
    <parent link="right_wrist_pitch_link"/>
    <child link="right_wrist_yaw_link"/>
    <!--  defined from CAD file-->
    <origin rpy="1.57079632679 -1.57079632679 0" xyz="0 0 0"/>
    <axis xyz="0 0 1"/>
    <!--rotates about z axis-->
    <!--limit effort and velocity picked arbitrarily check-->
    <limit effort="100.0" lower="-0.785398163397" upper="0.785398163397" velocity="10"/>
    <joint_properties damping="1.0" friction="0.0"/>
  </joint>
  <link name="right_wrist_yaw_link">
    <visual>
      <geometry>
        <mesh filename="package://dvrk_model/meshes/mtm/WristYaw.dae"/>
      </geometry>
    </visual>
    <collision>
      <geometry>
        <mesh filename="package://dvrk_model/meshes/mtm/WristYaw.STL"/>
      </geometry>
    </collision>
    <inertial>
      <mass value="0.2"/>
      <inertia ixx="0.1" ixy="0.0" ixz="0.0" iyy="0.1" iyz="0.0" izz="0.1"/>
    </inertial>
  </link>
  <joint name="right_wrist_roll_joint" type="revolute">
    <parent link="right_wrist_yaw_link"/>
    <child link="right_wrist_roll_link"/>
    <!-- -.039 & .055 defined from CAD file-->
    <origin rpy="-1.57079632679 1.57079632679 0" xyz="0 -.039 0"/>
    <axis xyz="0 0 -1"/>
    <!--rotates about y axis-->
    <!--limit effort and velocity picked arbitrarily check-->
    <limit effort="100.0" lower="-4.71238898038" upper="4.71238898038" velocity="10"/>
    <joint_properties damping="1.0" friction="0.0"/>
  </joint>
  <link name="right_wrist_roll_link">
    <visual>
      <geometry>
        <mesh filename="package://dvrk_model/meshes/mtm/WristRoll.dae"/>
      </geometry>
    </visual>
    <collision>
      <geometry>
        <mesh filename="package://dvrk_model/meshes/mtm/WristRoll.STL"/>
      </geometry>
    </collision>
    <inertial>
      <mass value="0.1"/>
      <inertia ixx="0.1" ixy="0.0" ixz="0.0" iyy="0.1" iyz="0.0" izz="0.1"/>
    </inertial>
  </link>
  <!-- add base link to match DVRK manual -->
  <joint name="right_base" type="fixed">
    <parent link="right_top_panel"/>
    <child link="right_base"/>
    <origin rpy="0 0 0" xyz="0 0 -0.190"/>
  </joint>
  <link name="right_base"/>
  <!-- add ee link to match DVRK manual -->
  <joint name="right_end_effector" type="fixed">
    <parent link="right_wrist_roll_link"/>
    <child link="right_ee_link"/>
    <origin rpy="0 3.14159265359 0" xyz="0 0 0.039"/>
  </joint>
  <link name="right_ee_link"/>
  <transmission name="tran1">
    <type>transmission_interface/SimpleTransmission</type>
    <joint name="right_outer_yaw_joint">
      <hardwareInterface>EffortJointInterface</hardwareInterface>
    </joint>
    <actuator name="motor1">
      <hardwareInterface>EffortJointInterface</hardwareInterface>
      <mechanicalReduction>1</mechanicalReduction>
    </actuator>
  </transmission>
  <transmission name="tran2">
    <type>transmission_interface/SimpleTransmission</type>
    <joint name="right_shoulder_pitch_joint">
      <hardwareInterface>EffortJointInterface</hardwareInterface>
    </joint>
    <actuator name="motor2">
      <hardwareInterface>EffortJointInterface</hardwareInterface>
      <mechanicalReduction>1</mechanicalReduction>
    </actuator>
  </transmission>
  <transmission name="tran3">
    <type>transmission_interface/SimpleTransmission</type>
    <joint name="right_elbow_pitch_joint">
      <hardwareInterface>EffortJointInterface</hardwareInterface>
    </joint>
    <actuator name="motor3">
      <hardwareInterface>EffortJointInterface</hardwareInterface>
      <mechanicalReduction>1</mechanicalReduction>
    </actuator>
  </transmission>
  <transmission name="tran4">
    <type>transmission_interface/SimpleTransmission</type>
    <joint name="right_wrist_platform_joint">
      <hardwareInterface>EffortJointInterface</hardwareInterface>
    </joint>
    <actuator name="motor4">
      <hardwareInterface>EffortJointInterface</hardwareInterface>
      <mechanicalReduction>1</mechanicalReduction>
    </actuator>
  </transmission>
  <transmission name="tran5">
    <type>transmission_interface/SimpleTransmission</type>
    <joint name="right_wrist_pitch_joint">
      <hardwareInterface>EffortJointInterface</hardwareInterface>
    </joint>
    <actuator name="motor5">
      <hardwareInterface>EffortJointInterface</hardwareInterface>
      <mechanicalReduction>1</mechanicalReduction>
    </actuator>
  </transmission>
  <transmission name="tran6">
    <type>transmission_interface/SimpleTransmission</type>
    <joint name="right_wrist_yaw_joint">
      <hardwareInterface>EffortJointInterface</hardwareInterface>
    </joint>
    <actuator name="motor6">
      <hardwareInterface>EffortJointInterface</hardwareInterface>
      <mechanicalReduction>1</mechanicalReduction>
    </actuator>
  </transmission>
  <transmission name="tran7">
    <type>transmission_interface/SimpleTransmission</type>
    <joint name="right_wrist_roll_joint">
      <hardwareInterface>EffortJointInterface</hardwareInterface>
    </joint>
    <actuator name="motor7">
      <hardwareInterface>EffortJointInterface</hardwareInterface>
      <mechanicalReduction>1</mechanicalReduction>
    </actuator>
  </transmission>
  <gazebo>
    <plugin filename="libgazebo_ros_control.so" name="gazebo_ros_control">
      <robotNamespace>/mtm</robotNamespace>
      <robotParam>/mtm/robot_description</robotParam>
      <robotSimType>gazebo_ros_control/DefaultRobotHWSim</robotSimType>
    </plugin>
  </gazebo>
  <!--    <gazebo>
      <plugin name="force_torque_sensor" filename="libgazebo_ros_f3d.so" >
        <bodyName>${prefix}bottom_parallel_link</bodyName>
        <frameName>${prefix}bottom_parallel_link</frameName>
        <topicName>/force_torque_feedback</topicName>
        <alwaysOn>true</alwaysOn>
        <updateRate>100.0</updateRate>
      </plugin>
    </gazebo>-->
</robot>

